<?xml version="1.0"?>
<robot name="mechanum_robot">
  <link name="base_link"/>
  <link name="body_link">
    <collision>
      <origin rpy="0 0 0" xyz="0 0 0.03"/>
      <geometry>
        <box size="0.28 0.18 0.13"/>
      </geometry>
    </collision>  
    <visual>
      <geometry>
        <mesh filename="package://mecanum_robot/meshes/body.dae"/>
      </geometry>
      <origin xyz="0.0 0.0 0" rpy="0.0 0.0 0"/>
    </visual>
  </link>
  <joint name="body_joint" type="fixed">
    <parent link="base_link"/>
    <child link="body_link"/>
    <origin xyz="0 0 0.090425"/>  
    <axis xyz="0 0 0"/>
  </joint>
  
  <link name="wheel_link">
    <collision>
      <origin rpy="0 0 0" xyz="0 0 0.05"/>
      <geometry>
        <box size="0.4 0.3 0.1"/>
      </geometry>
    </collision>
    <visual>
      <geometry>
        <mesh filename="package://mecanum_robot/meshes/wheels.dae"/>
      </geometry>
      <origin xyz="0.0 0.0 0" rpy="0.0 0.0 0"/>
    </visual>
  </link>

  <joint name="wheel_joint" type="fixed">
    <parent link="base_link"/>
    <child link="wheel_link"/>
    <origin xyz="0 0 0 "/>  
    <axis xyz="0 0 0"/>
  </joint>

  <link name="zed2_link">
    <collision>
      <origin rpy="0 0 0" xyz="-0.01 0 0.01"/>
      <geometry>
        <box size="0.04 0.16 0.035"/>
      </geometry>
    </collision>  
    <visual>
      <geometry>
        <mesh filename="package://mecanum_robot/meshes/zed2.dae"/>
      </geometry>
      <origin xyz="0.0 0.0 0" rpy="0.0 0.0 0"/>
    </visual>
  </link>

  <joint name="zed2_joint" type="fixed">
    <parent link="base_link"/>
    <child link="zed2_link"/>
    <origin xyz="0.09 0 0.235 "/>  
    <axis xyz="0 0 0"/>
  </joint>  

  <link name="arm_pan_link">
    <collision>
      <origin rpy="0 0 0" xyz="0 0 0"/>
      <geometry>
        <cylinder length="0.04" radius="0.09"/>
      </geometry>
    </collision>
    <visual>
      <geometry>
        <mesh filename="package://mecanum_robot/meshes/arm_pan.dae"/>
      </geometry>
      <origin xyz="0.0 0.0 0" rpy="0.0 0.0 0"/>
    </visual>
  </link>

  <joint name="arm_pan_joint" type="revolute">
    <parent link="base_link"/>
    <child link="arm_pan_link"/>
    <origin xyz="-0.054 0 0.22 "/>  
    <axis xyz="0 0 1"/>
    <limit lower="-1.0" upper="1.0" effort="0" velocity="0"/>
  </joint>

  <link name="arm_tilt1_link">
    <collision> 
      <origin rpy="0 0.1 0" xyz="-0.0 0 0.11"/> 
      <geometry>
        <box size="0.05 0.12 0.22"/>
      </geometry>
    </collision>  
    <visual>
      <geometry>
        <mesh filename="package://mecanum_robot/meshes/arm_tilt1.dae"/>
      </geometry>
      <origin xyz="0.0 0.0 0" rpy="0.0 0.0 0"/>
    </visual>
  </link>

  <joint name="arm_tilt1_joint" type="revolute">
    <parent link="arm_pan_link"/>
    <child link="arm_tilt1_link"/>
    <origin xyz="0.01 0 0.02 "/>  
    <axis xyz="0 1 0"/>
    <limit lower="-0.6" upper="1.3" effort="0" velocity="0"/>
  </joint>

  <link name="arm_tilt2_link">
    <collision> 
      <origin rpy="0 0.22 0" xyz="-0.03 0 0.13"/> 
      <geometry>
        <box size="0.06 0.08 0.26"/>
      </geometry>
    </collision>
    <visual>
      <geometry>
        <mesh filename="package://mecanum_robot/meshes/arm_tilt2.dae"/>
      </geometry>
      <origin xyz="0.0 0.0 0" rpy="0.0 0.0 0"/>
    </visual>
  </link>

  <joint name="arm_tilt2_joint" type="revolute">
    <parent link="arm_tilt1_link"/>
    <child link="arm_tilt2_link"/>
    <origin xyz="0 0 0.214 "/>  
    <axis xyz="0 1 0"/>
    <limit lower="-0.6" upper="1.5" effort="0" velocity="0"/>
  </joint>

</robot>